Workbook

Sheet Canvas
A1: PARCERIAS | B1: ATIVIDADES-CHAVE | C1: PROPOSTA DE VALOR | D1: RELACIONAMENTOS COM CLIENTES | E1: SEGMENTOS DE CLIENTES
A2: Sócios, no risco: | B2: · Teste manual com 3 empresas
A3: · Desenvolvedor, TI | B3: · Desenvolvimento estrutura | C3: ü Avaliar a situação econômico-financeira de empresas, via internet, automatizada; | D3: · Autosserviço interativo via internet | E3: MEI, Micro e Pequenas Empresas
A4: · Vendas, Marketing | B4: · Banco de dados | C4: ü Contribuir para melhoria de decisões e otimizar resultados; | D4: · Cliente digita as informações (conforme lista de ENTRADA DE DADOS)
B5: · Fórmulas para indicadores | D5: · Sistema emite relatório
B6: · Indexação relatório recomendações | C6: VANTAGEM COMPETITIVA:
B7: · prototipagem | C7: ü Atendimento específico de necessidades de empresários;
B8: · MVP: Validação da plataforma | C8: ü Fácil operacionalização;
B9: · Página inicial | C9: ü Navegação rápida;
B10: · Estratégia de marketing | C10: ü Simplicidade;
B11: · Produção mídia | C11: ü Segurança;
B12: · Entrada de Dados (cliente) | C12: ü Uso intuitivo;
B13: · Tratamento das informações e Emissão de Relatório | C13: ü Responsivo
B14: · Registro, Hospedagem, INPI
B15: · Suporte técnico
B16: · Atualização da plataforma
B17: · Monitoramento
B19: RECURSOS-CHAVE | D19: CANAIS
B20: · Desenvolvimento sistema web | D20: Tráfego pago, Google ads
B21: · Marketing | D21: Instagram, Facebook, Twiter, Youtube, linkedin, whats app
B22: · SEO: Otimização para motores busca
A24: ESTRUTURA DE CUSTOS | D24: FONTES DE RECEITAS
A25: • Desenvolvimento R$ • Registro, Domínio, Hospedagem, VPS,SSL, Provedor, Banco de dados, Nuvem R$ • Teste, MVP, validação, marketing, divulgação na mídia e redes sociais R$ • Manutenção, Suporte: mensal R$ | D25: R$ assinatura anual Ou Grátis, se houver convênio/patrocínio: Sebrae, BB, CNC, CNI, BNB, CDL, Federações

Sheet Insights
A1: INSIGHTS E DESAFIOS | B1: OBSERVAÇÕES E ENCAMINHAMENTOS
A2: Quantidade de CNPJ existentes no país | B2: MDIC, Set/23: 21 milhões
A3: Quantidade de MEI existentes no país | B3: RFB, Set/23: 15 milhões IBGE, 2021: 13 milhões = 69% do total; 50% serviços, 29%o ficinas
A4: Quantidade de micro empresas existentes no país | B4: SEBRAE, 2023: 6 milhões de MPE
A5: Quantidade de pequenas empresas existentes no país | B5: Menos de 1 milhão
A6: Estimativa quantitativa de micro e pequenas empresas como público-alvo?
A7: Metas evolluta de assinantes?
A8: Esse público tem pouca orientação sobre a importância desse tipo de informação para o negócio
A9: Há dificuldade de contadores cobrarem honorário justo pelos serviços contábeis obrigatórios
A10: Plataforma com informações consistentes
A11: Público-alvo precisa compreender a importância do DEF on line
A12: Há pessoas que sabem da importância mas não valorizam
A13: Acredito seria utilizado sim. Inicialmente, pelo menos. Hoje se testa aplicativo diariamente, mas também são descartados na mesma velocidade se não atendem à expectativa do usuário
A14: Se não custar muito caro produzir e disponibilizar para os usuários, pode valer a pena testar a viabilidade de oferecer serviços a partir do app
A15: A empresa precisa ficar consultando o aplicativo em quando tempo em média?
A16: Como é que clientes tomam conhecimento do DEF on line e chegam ao produto?
A17: Declaração do atual cenário do projeto Início dos levantamentos do problema, oportunidade e/ou desafio que darão origem ao projetos pontos declarados e apresentados por agentes envolvidos foram postos de maneira clara e realista utilize ferramentas como: Análise de SWOT ou Realização de Workshop para explorar melhor o problema.
... A28: ideia precisa atrair o interesse e a atenção
A29: suporte de especialista em finanças para esclarecer dúvidas por email | B29: eb@ebparcerias.com
A30: a responsabilidade pela qualidade das informações alimentadas na Entrada de Dados é do usuário assinante, esclarecido que a assertividade e análise técnica depende da coerência dos dados digitados | B30: assinalamento pelo assinante
A31: estrutura aberta para permitir, em novas versões, a integração com TEF, por exemplo, dashboard, gráficos etc
A32: produto inédito, único
A33: qual o problema o DEF on line vai resolver
A34: escolher pessoas para apontar pontos cegos do produto
A35: experiência do usuário
A36: nenhum usuário vai pagar mais do que o valor que percebe
A37: armazenamento em nuvem
A38: saber se os MEI, Micro e Pequenos empresários tê interesse no APP DEF on line
A39: definir problema/oportunidade
A40: criar protótipo
A41: testar protótipo
A42: congregar afiliados para divulgação com comissão
... A78: Antecipação a problemas; Acompanhamento efetivo do desempenho do negócio; Identificação tempestiva e preventiva de anomalias;
A79: PROPOSTA DE VALOR: Avaliar a situação econômico-financeira do negócio, via APP ou site | B79: https://analistamodelosdenegocios.com.br/canvas-da-proposta-de-valor/
A80: Fácil operacionalização; Navegação rápida; Simplicidade; Segurança; Uso intuitivo; Responsivo
A81: Opção para imprimir ou salvar em pdf o Relatório com indicadores e recomendações técnicas em linguagem amigável, objetiva e clara
A82: cronograma de desenvolvimento da estrutura básica do MVP (APP IOS/Android e site)
A83: acesso do usuário para alimentar a entrada de dados somente após cadastro login (CPNJ/CPF, email, senha) e conferência do pagamento da assinatura, no prazo de validadde (até 12 meses após a data do pagamento)
A84: estratégias de divulgação em redes sociais
A85: Testar a ideia
...

Sheet Ações
A1: DATA | B1: AÇÃO | C1: RESPONSÁVEL | D1: INTERVENIENTE | E1: FOLLOW UP | F1: STATUS | G1: ENCAMINHAMENTOS
A2: 45224 | B2: Firmar NDA sobre DEF on line | C2: Alex | D2: EBC | E2: 45247 | F2: DONE | G2: Termo assinado em 17-11-2023
A3: 45247 | B3: Confirmar interesse na sociedade e no risco desenvolver MVP, assumir TI | C3: Alex | E3: 45252 | F3: DONE
A4: 45252 | B4: Sondar potencial parceiro que assuma MKT/comercial, no risco | C4: Alex | E4: 45319 | F4: DOING
A5: 45252 | B5: Sondar potencial parceiro que assuma MKT/comercial, no risco | C5: EBJ | D5: EBC | E5: 45319 | F5: DOING
A6: 45252 | B6: Consultar alguns contadores sobre a efetiva necessidade do produto por parte dos micro e pequenos empresários | C6: EBC | E6: 45266 | F6: DOING | G6: recebendo opiniões, questionamentos e teste (Bernardo, Paulo Vizeu, Paula, Ana Gurgel, Danilo Brito, Demotier, Eliésio, José Augusto, Josenilton, Damacena, Sidney e outros 40 )
A7: 45255 | B7: Elaborar cronograma do desenvolvimento do MPV do APP/site | C7: Alex | E7: 45319 | F7: TO DO
A8: 45259 | B8: Desenvolver MoCap | C8: Alex | E8: 45342 | F8: TO DO
A9: 45252 | B9: Compartilhar minutas básicas do modelo de negócios, estrutura, entrada de dados, relatório, contrato de parceria e assinatura por usuários | C9: EBC | D9: Alex e EBJ | E9: 45275 | F9: DONE | G9: Enviado para análise por Alex e EBJ
A10: 45252 | B10: Análise minutas: modelo de negócios, estrutura, entrada de dados, relatório, contrato de parceria e assinatura por usuários | C10: Alex | D10: EBJ | E10: 45319 | F10: DOING

Sheet Entrada de dados
A1: CNPJ ou/CPF
A2: Setor de atuação (Indústria, Comércio, Serviços?)
A3: E-mail
A4: Disponibilidades em caixa, bancos, aplicações (o total, nesta data, independente do prazo)
A5: Montate das duplicatas, cheques e cartão de crédito a receber (R$ mil), (o total, nesta data, independente do prazo)
A6: Valor do estoque nesta data (R$ mil)
A7: Valor venal de mercado estimado dos imóveis, equipamentos e veículos (R$ mil)
A8: Saldo devedor dos empréstimos, financiamentos e outras Dívidas a pagar (R$ mil), (o total, nesta data, independente do prazo)
A9: Débitos com fornecedores (R$ mil), (o total, nesta data, independente do prazo)
A10: Valor médio mensal das compras realizadas nos últimos 12 meses (R$ mil)
A11: Valor médio mensal das vendas realizadas nos últimos 12 meses (R$ mil)
A12: Prazo médio de pagamento das compras: (dias):
... A21: ( ) Quero receber mailing da EB Parcerias

Sheet Relatório
A1: CNPJ ou CPF | B1: ='Entrada de dados'!B1 -> 0
A2: Setor de atuação | B2: ='Entrada de dados'!B2 -> 0
A3: EMAIL | B3: ='Entrada de dados'!B3 -> 0
A4: RAZÃO SOCIAL | B4: API de consulta dados públicos na RFB, a partir do CNPJ
A5: NOME FANTASIA | B5: "
A6: DATA FUNDAÇÃO | B6: "
A7: CNAE PRINCIPAL | B7: "
A8: MUNICÍPIO | B8: "
A9: UF | B9: "
A10: SITUAÇÃO | B10: "
A12: BALANÇO E DRE ADAPTADOS | B12: (o balanço não precisa ser mostrado no relatório) | C12: campos hachurados não são mostrados
A13: Disponibilidades | B13: ='Entrada de dados'!B4 -> 0
A14: ACF | B14: =B13 -> 0
A15: Clientes | B15: ='Entrada de dados'!B5 -> 0
A16: Estoques | B16: ='Entrada de dados'!B6 -> 0
A17: ACC | B17: =B15+B16 -> 0
A18: AC | B18: =B14+B17 -> 0
A19: Imobilizado | B19: ='Entrada de dados'!B7 -> 0
A20: ANC | B20: =B19 -> 0
A21: Ativo | B21: =B18+B20 -> 0
A22: Empréstimos | B22: ='Entrada de dados'!B8 -> 0
A23: PCF | B23: =B22 -> 0
A24: Fornecedores | B24: ='Entrada de dados'!B9 -> 0
A25: PCC | B25: =B24 -> 0
A26: PC | B26: =B23+B25 -> 0
A27: PL | B27: =B21-B26 -> 0
A28: Passivo | B28: =B26+B27 -> 0
A29: Vendas (ROB, ROL) | B29: ='Entrada de dados'!B11 -> 0
A30: Compras (CPF, CMV, CSV) | B30: ='Entrada de dados'!B10 -> 0
A31: Lucro Bruto (MB) | B31: =B29-B30 -> 0
A32: Despesas fixas | B32: ='Entrada de dados'!B16 -> 0
A33: Despesas variáveis | B33: ='Entrada de dados'!B17 -> 0
A34: Lucro Operacional (Ebitda) | B34: =B31-B32-B33 -> 0
A35: Despesas financeiras | B35: ='Entrada de dados'!B18 -> 0
A36: Lucro Operacional Líquido (MOL) | B36: =B34-B35 -> 0
A37: Indicadores | B37: Fórmula | C37: Situação em DDMMAAAA, APP assume automaticamente data/hora preenchimento Entrada de Dados | D37: QUANTO MAIOR
A38: Margem Bruta | B38: lucro bruto / vendas * 100 | C38: =B31/B29*100 -> #DIV/0! | D38: MELHOR
A39: Margem Operacional (EBITDA): mede a eficiência em produzir lucros por meio das vendas | B39: Lucro operacional antes IR e Desp Fin / ROL * 100 | C39: =B34/B29*100 -> #DIV/0! | D39: MELHOR
A40: Margem Operacional Líquida (MOL): parcela operacional de lucro obtida sobre as vendas | B40: LOL / ROL * 100 | C40: =B36/B29*100 -> #DIV/0! | D40: MELHOR
A41: Relação Dívida Líquida / Ebitda: demonstra o número de períodos que uma empresa levaria para pagar sua dívida líquida | B41: ( (PCF+Fin.LP) -ACF) / Ebitda | C41: =(B23-B14)/B34 -> #DIV/0! | D41: PIOR
...

Sheet Assinatura
A1: ID, Usuário (CNPJ ou CPF)
A2: email
A3: senha vigente?
A4: Pagamento Assinatura (ddmmaa)
A5: DEF realizados (ddmmaa)
A10: ASSINATURA ANUAL
A11: Não parcelar
A12: "nenhum usuário vai pagar mais do que o valor que percebe"
A13: acesso do usuário para alimentar a entrada de dados somente após cadastro login (CPNJ/CPF, email, senha) e conferência do pagamento da assinatura, no prazo de validadde (até 12 meses após a data do pagamento)
A14: alerta responsabilidade assinante pela consistência das informações digitadas na Entrada de Dados
A17: SUGESTÕES DE VALOR
A18: 360
A19: 150
A20: se incrementar com gráficos, dar uma enfeitada, tirar a imagem de ser só um excel... 1/2 salario
A21: degustação 1 mês grátis
A31: PAGAMENTO
A32: Chave Pix | B32: 28.261.669/0001-56
A33: Dados Bancários | B33: Banco: 077
B34: Agência: 0001
B35: Conta: 28166130-8
B36: CNPJ: 28261669/0001/-56
B37: EB PARCERIAS LTDA

Sheet lista
A1: TO DO
A2: DOING
A3: DONE
